Workbook

Sheet Org
L2: ENCO - SOHAR
B5: ENCO - INDUSTRIAL AREA | M5: ENCO - SOHAR PORT (VALE)
I8: CONTRACTOR PARKING AREA | L8: YARD 2 | P8: YARD 3 | T8: LAYDOWN
S11: MODULE OFFLOADING / IPMT | V11: TSF
B13: CRANE | I13: CRANE | L13: CRANE | P13: CRANE | V13: CRANE
B14: 40T TADANO CRAWLER CRANE | E14: 1 | I14: 70T TELESCOPIC CRANE 6427MH (RENTAL) | J14: 1 | L14: 100T TELESCOPIC CRANE 3988DS (RENTAL) | M14: 1 | P14: 70T CRAWLER CRANE 6901YS (RENTAL) | Q14: 1 | V14: 70T TELESCOPIC CRANE 3155MH (RENTAL) | W14: 1
B15: 80T GROVE TELESCOPIC CRANE | E15: 1 | I15: 130T CRAWLER CRANE 2854BA (RENTAL) | J15: 1 | L15: 150T CRAWLER CRANE 3285LH (RENTAL) | M15: 1 | P15: 150T CRAWLER CRANE3286LH (RENTAL) | Q15: 1 | V15: 70T CRAWLER CRANE 9068HW (RENTAL) | W15: 1
B16: 100T SANY TELESCOPIC CRANE | E16: 1 | V16: 100T TELESCOPIC CRANE 9480ML (RENTAL) | W16: 1
I17: MANLIFT | L17: MANLIFT | P17: GENERATOR
B18: MANLIFT | I18: 22M HAULOTTE MANLIFT 21648446 | J18: 1 | L18: 22M LCMG MANLIFT LWJAB202KS3720001 | M18: 1 | P18: 40KVA CUMMINS GENERATOR | Q18: 1 | V18: HI-UP
B19: 14M HAULOTE MANLIFT | E19: 1 | I19: 22M HAULOTTE MANLIFT 2164847 | J19: 1 | L19: 28M LCMG MANLIFT LWJAB262ES3739913 | M19: 1 | V19: 7T HI-UP 1077DS | W19: 1
B20: 41M JLG MANLIFT | E20: 1
I21: TOWER LIGHT | L21: GENERATOR | V21: FORKLIFT
B22: FORKLIFT | I22: 7.2KW TOWER LIGHT 2702250311 (ENCO) | J22: 1 | L22: 22KVA GENERATOR | M22: 1 | V22: 14T FORKLIFT 2088LD | W22: 1
B23: 7T HYSTER FORKLIFT | E23: 1 | I23: TOWER LIGHT 2702250313 (ENCO) | J23: 1
V24: TELEHANDLER
B25: BUS | I25: PICK-UP | M25: TRAILER | V25: 4T JCB TELEHANDLER 5630YW | W25: 1
B26: 22 SEAT BUS 2746MB (DAMAGED) | E26: 1 | I26: PICK-UP 4265BM (RENTAL) | J26: 1 | M26: FLATBED TRAILER 3576MD (RENTAL) | P26: 1
V27: TRAILER
B28: TRAILER | I28: SCISSOR LIFT | M28: PICK-UP | V28: FLATBED TRAILER 7465BM | W28: 1
B29: FLATBED TRAILER | E29: 1 | I29: 12M SCISSOR LIFT 20251128-01 | J29: 1 | M29: PICK-UP 2819DA (RENTAL) | P29: 1 | V29: RENAULT LOWBED TRAILER 2939ML | W29: 1
I30: 12M SCISSOR LIFT 20251128-02 | J30: 1
B31: COMPRESSOR | I31: 12M SCISSOR LIFT 20251128-03 | J31: 1 | V31: SCISSOR LIFT
B32: KAESER COMPRESSOR | E32: 1 | V32: 12M SCISSOR LIFT 20251128-04 | W32: 1
I33: BUS
I34: 55 SEAT BUS (RENTAL) | J34: 1 | V34: GENERATOR
V35: 300/330KVA CUMMINS GENERATOR | W35: 1
V36: 35/40KVA CUMMINS GENERATOR | W36: 1
V38: TOWER LIGHT
V39: 6.5 KW TOWER LIGHT LED LD1000JN202510071 | W39: 1
V40: 7.2KW TOWER LIGHT 2702250306 | W40: 1
V41: 7.2KW TOWER LIGHT 2025121001 | W41: 1
V43: PICK-UP
V44: PICK-UP 569WA (RENTAL) | W44: 1
V45: PICK-UP 15BM (RENTAL) | W45: 1
V47: BUS
V48: 55 SEAT BUS 7885YM (RENTAL) | W48: 1
V49: 22 SEAT BUS 2498YD | W49: 1
V50: 22 SEAT BUS 8028WA | W50: 1
V51: 15 SEAT BUS 9405YR | W51: 1
...

Sheet Cost
B2: AREA | C2: =Org!B5 -> ENCO - INDUSTRIAL AREA | D2: Qty | E2: SUPPLY RATE | I2: CONTRACT UNIT RATE
E3: Hourly | F3: Daily | G3: Weekly | H3: Monthly | I3: Hourly | J3: Daily | K3: Weekly | L3: Monthly
B4: 1 | C4: =Org!B14 -> 40T TADANO CRAWLER CRANE | D4: =Org!E14 -> 1 | E4: OWNED BY ENCO | I4: N/A | J4: N/A | K4: N/A | L4: N/A
B5: 2 | C5: =Org!B15 -> 80T GROVE TELESCOPIC CRANE | D5: =Org!E15 -> 1 | E5: OWNED BY ENCO | I5: 0 | J5: 0 | K5: 4880 | L5: 12200
B6: 3 | C6: =Org!B16 -> 100T SANY TELESCOPIC CRANE | D6: =Org!E16 -> 1 | E6: OWNED BY ENCO | I6: 0 | J6: 0 | K6: 4880 | L6: 12200
B7: 4 | C7: =Org!B19 -> 14M HAULOTE MANLIFT | D7: =Org!E19 -> 1 | E7: OWNED BY ENCO | I7: 11 | J7: 95 | K7: 518 | L7: 1550
B8: 5 | C8: =Org!B20 -> 41M JLG MANLIFT | D8: =Org!E20 -> 1 | E8: OWNED BY ENCO | I8: 21 | J8: 182 | K8: 1000 | L8: 3000
B9: 6 | C9: =Org!B23 -> 7T HYSTER FORKLIFT | D9: =Org!E23 -> 1 | E9: OWNED BY ENCO | I9: 15 | J9: 135 | K9: 735 | L9: 2200
B10: 7 | C10: =Org!B26 -> 22 SEAT BUS 2746MB (DAMAGED) | D10: =Org!E26 -> 1 | E10: OWNED BY ENCO | I10: N/A | J10: N/A | K10: N/A | L10: N/A
B11: 8 | C11: =Org!B29 -> FLATBED TRAILER | D11: =Org!E29 -> 1 | E11: OWNED BY ENCO | I11: 20 | J11: 175 | K11: 940 | L11: 2800
B12: 9 | C12: =Org!B32 -> KAESER COMPRESSOR | D12: =Org!E32 -> 1 | E12: OWNED BY ENCO | I12: N/A | J12: N/A | K12: N/A | L12: N/A
B14: AREA | C14: =Org!I8 -> CONTRACTOR PARKING AREA | D14: Qty | E14: SUPPLY RATE | I14: CONTRACT UNIT RATE
E15: Hourly | F15: Daily | G15: Weekly | H15: Monthly | I15: Hourly | J15: Daily | K15: Weekly | L15: Monthly
B16: 1 | C16: =Org!I14 -> 70T TELESCOPIC CRANE 6427MH (RENTAL) | D16: =Org!J14 -> 1 | E16: 0 | F16: 0 | G16: 0 | H16: 2400 | I16: 0 | J16: 454 | K16: 2500 | L16: 7500
B17: 2 | C17: =Org!I15 -> 130T CRAWLER CRANE 2854BA (RENTAL) | D17: =Org!J15 -> 1 | E17: 0 | F17: 0 | G17: 0 | H17: 6800 | I17: 0 | J17: 0 | K17: 6730 | L17: 16380
B18: 3 | C18: =Org!I19 -> 22M HAULOTTE MANLIFT 2164847 | D18: =Org!J19 -> 1 | E18: OWNED BY ENCO | I18: 15 | J18: 135 | K18: 740 | L18: 2200
B19: 4 | C19: =Org!I23 -> TOWER LIGHT 2702250313 (ENCO) | D19: =Org!J23 -> 1 | E19: OWNED BY ENCO | I19: 8.6 | J19: 34 | K19: 185 | L19: 550
B20: 5 | C20: =Org!I22 -> 7.2KW TOWER LIGHT 2702250311 (ENCO) | D20: =Org!J22 -> 1 | E20: OWNED BY ENCO | I20: 8.6 | J20: 34 | K20: 185 | L20: 550
B21: 6 | C21: =Org!I26 -> PICK-UP 4265BM (RENTAL) | D21: =Org!J26 -> 1 | E21: 0 | F21: 0 | G21: 0 | H21: 300 | I21: 0 | J21: 60 | K21: 480 | L21: 1200
B22: 7 | C22: =Org!I29 -> 12M SCISSOR LIFT 20251128-01 | D22: =Org!J29 -> 1 | E22: OWNED BY ENCO | I22: 10 | J22: 85 | K22: 470 | L22: 1400
B23: 8 | C23: =Org!I30 -> 12M SCISSOR LIFT 20251128-02 | D23: =Org!J30 -> 1 | E23: OWNED BY ENCO | I23: 10 | J23: 85 | K23: 470 | L23: 1400
B24: 9 | C24: =Org!I31 -> 12M SCISSOR LIFT 20251128-03 | D24: =Org!J31 -> 1 | E24: OWNED BY ENCO | I24: 10 | J24: 85 | K24: 470 | L24: 1400
B25: 10 | C25: =Org!I34 -> 55 SEAT BUS (RENTAL) | D25: =Org!J34 -> 1 | E25: 0 | F25: 0 | G25: 0 | H25: 600 | I25: N/A | J25: N/A | K25: N/A | L25: N/A
B27: AREA | C27: =Org!L8 -> YARD 2 | D27: Qty | E27: SUPPLY RATE | I27: CONTRACT UNIT RATE
E28: Hourly | F28: Daily | G28: Weekly | H28: Monthly | I28: Hourly | J28: Daily | K28: Weekly | L28: Monthly
B29: 1 | C29: =Org!L14 -> 100T TELESCOPIC CRANE 3988DS (RENTAL) | D29: =Org!M14 -> 1 | E29: 0 | F29: 0 | G29: 0 | H29: 5000 | I29: 0 | J29: 0 | K29: 4880 | L29: 12200
B30: 2 | C30: =Org!L15 -> 150T CRAWLER CRANE 3285LH (RENTAL) | D30: =Org!M15 -> 1 | E30: 0 | F30: 0 | G30: 0 | H30: 7000 | I30: 0 | J30: 0 | K30: 7480 | L30: 18700
B31: 3 | C31: =Org!L18 -> 22M LCMG MANLIFT LWJAB202KS3720001 | D31: =Org!M18 -> 1 | E31: OWNED BY ENCO | I31: 15 | J31: 135 | K31: 740 | L31: 2200
B32: 4 | C32: =Org!L19 -> 28M LCMG MANLIFT LWJAB262ES3739913 | D32: =Org!M19 -> 1 | E32: OWNED BY ENCO | I32: 15 | J32: 135 | K32: 740 | L32: 2200
B33: 5 | C33: =Org!L22 -> 22KVA GENERATOR | D33: =Org!M22 -> 1 | E33: OWNED BY ENCO | I33: 7.85 | J33: 31 | K33: 170 | L33: 500
B35: AREA | C35: =Org!P8 -> YARD 3 | D35: Qty | E35: SUPPLY RATE | I35: CONTRACT UNIT RATE
E36: Hourly | F36: Daily | G36: Weekly | H36: Monthly | I36: Hourly | J36: Daily | K36: Weekly | L36: Monthly
B37: 1 | C37: =Org!P14 -> 70T CRAWLER CRANE 6901YS (RENTAL) | D37: =Org!Q14 -> 1 | E37: 0 | F37: 0 | G37: 0 | H37: 3800 | I37: 0 | J37: 0 | K37: 3950 | L37: 10950
B38: 2 | C38: =Org!P15 -> 150T CRAWLER CRANE3286LH (RENTAL) | D38: =Org!Q15 -> 1 | E38: 0 | F38: 0 | G38: 0 | H38: 7000 | I38: 0 | J38: 0 | K38: 7480 | L38: 18700
B39: 3 | C39: =Org!P18 -> 40KVA CUMMINS GENERATOR | D39: =Org!Q18 -> 1 | E39: OWNED BY ENCO | I39: 8.6 | J39: 34 | K39: 185 | L39: 550
B40: 4 | C40: =Org!M26 -> FLATBED TRAILER 3576MD (RENTAL) | D40: =Org!P26 -> 1 | E40: 0 | F40: 0 | G40: 0 | H40: 1400 | I40: 20 | J40: 175 | K40: 940 | L40: 2800
B41: 5 | C41: =Org!M29 -> PICK-UP 2819DA (RENTAL) | D41: =Org!P29 -> 1 | E41: 0 | F41: 0 | G41: 0 | H41: 300 | I41: 0 | J41: 60 | K41: 480 | L41: 1200
B43: AREA | C43: =Org!V11 -> TSF | D43: Qty | E43: SUPPLY RATE | I43: CONTRACT UNIT RATE
E44: Hourly | F44: Daily | G44: Weekly | H44: Monthly | I44: Hourly | J44: Daily | K44: Weekly | L44: Monthly
B45: 1 | C45: =Org!V14 -> 70T TELESCOPIC CRANE 3155MH (RENTAL) | D45: =Org!W14 -> 1 | E45: 0 | F45: 0 | G45: 0 | H45: 2400 | I45: 0 | J45: 454 | K45: 2500 | L45: 7500
...
