Workbook
Name ElectricalWorks: Tasks!$H2:$H99990
Name Finalization: Tasks!$K2:$K99990
Name GroutingWorks: Tasks!$F2:$F99990
Name InstrumentationWorks: Tasks!$I2:$I999990
Name MaterialHandling: Tasks!$C$2:$C$37000
Name MobilizationPreparation: Tasks!$B$2:$B$900
Name PaintingCoating: Tasks!$J2:$J999990
Name PipingWorks: Tasks!$G$2:$G$1048576
Name SteelStructureWorks: Tasks!$D2:$D9990

Sheet Cumulative

Sheet March 2026
A1: No | B1: Filled By | C1: Date | D1: Company | E1: Name Surname | F1: Column1 | G1: Designation | H1: Man/Equ | I1: Category | J1: Area | K1: Reference | L1: Item Tag | M1: Shift | N1: Manhours | O1: Main Activity | P1: Sub Act | Q1: Sub-Sub Act | R1: Note | S1: JSA LOCATION
A2: =IF(C2="","",MAX($A$1:A1)+1) -> 1 | B2: Ebin | C2: 46082 | D2: =_xlfn.XLOOKUP(Table134526_79101120212223242526[[#This Row],[Name Surname]],Manpower!$C$4:$C$1048576,Manpower!$B$4:$B$1048576,"") -> Riyan Al Khaleej | E2: 100T TELESCOPIC CRANE (RENTAL)-ZL | F2: =_xlfn.XLOOKUP(Table134526_79101120212223242526[[#This Row],[Name Surname]],Manpower!C:C,Manpower!D:D,) -> #N/A | G2: =_xlfn.XLOOKUP(Table134526_79101120212223242526[[#This Row],[Name Surname]],Manpower!$C$4:$C$1048576,Manpower!$F$4:$F$1048576,"") -> 100T Telescopic Crane | H2: =_xlfn.XLOOKUP(Table134526_79101120212223242526[[#This Row],[Name Surname]],Manpower!$C$4:$C$1048576,Manpower!$H$4:$H$1048576,"") -> Equipment | I2: =_xlfn.XLOOKUP(Table134526_79101120212223242526[[#This Row],[Name Surname]],Manpower!$C$4:$C$1048576,Manpower!$H$4:$H$1048576,"") -> Equipment | J2: Yard 3 | K2: Dismantling | L2: DBD Bld | M2: Day | N2: 8 | O2: Steel Structure Works | P2: Dismantling | Q2: Dismantling | R2: _
A3: =IF(C3="","",MAX($A$1:A2)+1) -> 2 | B3: Ebin | C3: 46082 | D3: =_xlfn.XLOOKUP(Table134526_79101120212223242526[[#This Row],[Name Surname]],Manpower!$C$4:$C$1048576,Manpower!$B$4:$B$1048576,"") -> Encogroup | E3: Ashwini Kumar | F3: =_xlfn.XLOOKUP(Table134526_79101120212223242526[[#This Row],[Name Surname]],Manpower!C:C,Manpower!D:D,) -> 127414586 | G3: =_xlfn.XLOOKUP(Table134526_79101120212223242526[[#This Row],[Name Surname]],Manpower!$C$4:$C$1048576,Manpower!$F$4:$F$1048576,"") -> Electrician | H3: =_xlfn.XLOOKUP(Table134526_79101120212223242526[[#This Row],[Name Surname]],Manpower!$C$4:$C$1048576,Manpower!$H$4:$H$1048576,"") -> Manpower | I3: =_xlfn.XLOOKUP(Table134526_79101120212223242526[[#This Row],[Name Surname]],Manpower!$C$4:$C$1048576,Manpower!$H$4:$H$1048576,"") -> Manpower | J3: Yard 3 | K3: Dismantling | L3: DBD Bld | M3: Day | N3: 5 | O3: Electrical Works | P3: Electrical Works | Q3: Dismantling | R3: _
A4: =IF(C4="","",MAX($A$1:A3)+1) -> 3 | B4: Ebin | C4: 46082 | D4: =_xlfn.XLOOKUP(Table134526_79101120212223242526[[#This Row],[Name Surname]],Manpower!$C$4:$C$1048576,Manpower!$B$4:$B$1048576,"") -> Encogroup | E4: Atif Rasheed | F4: =_xlfn.XLOOKUP(Table134526_79101120212223242526[[#This Row],[Name Surname]],Manpower!C:C,Manpower!D:D,) -> 127331574 | G4: =_xlfn.XLOOKUP(Table134526_79101120212223242526[[#This Row],[Name Surname]],Manpower!$C$4:$C$1048576,Manpower!$F$4:$F$1048576,"") -> Permit Receiver | H4: =_xlfn.XLOOKUP(Table134526_79101120212223242526[[#This Row],[Name Surname]],Manpower!$C$4:$C$1048576,Manpower!$H$4:$H$1048576,"") -> Manpower | I4: =_xlfn.XLOOKUP(Table134526_79101120212223242526[[#This Row],[Name Surname]],Manpower!$C$4:$C$1048576,Manpower!$H$4:$H$1048576,"") -> Manpower | J4: Yard 3 | K4: Dismantling | L4: DBD Bld | M4: Day | N4: 8 | O4: Steel Structure Works | P4: Dismantling | Q4: Dismantling | R4: _
A5: =IF(C5="","",MAX($A$1:A4)+1) -> 4 | B5: Ebin | C5: 46082 | D5: =_xlfn.XLOOKUP(Table134526_79101120212223242526[[#This Row],[Name Surname]],Manpower!$C$4:$C$1048576,Manpower!$B$4:$B$1048576,"") -> Encogroup | E5: Ebin Ben | F5: =_xlfn.XLOOKUP(Table134526_79101120212223242526[[#This Row],[Name Surname]],Manpower!C:C,Manpower!D:D,) -> 116589569 | G5: =_xlfn.XLOOKUP(Table134526_79101120212223242526[[#This Row],[Name Surname]],Manpower!$C$4:$C$1048576,Manpower!$F$4:$F$1048576,"") -> Mechanical Engineer | H5: =_xlfn.XLOOKUP(Table134526_79101120212223242526[[#This Row],[Name Surname]],Manpower!$C$4:$C$1048576,Manpower!$H$4:$H$1048576,"") -> Manpower | I5: =_xlfn.XLOOKUP(Table134526_79101120212223242526[[#This Row],[Name Surname]],Manpower!$C$4:$C$1048576,Manpower!$H$4:$H$1048576,"") -> Manpower | J5: Yard 3 | K5: Dismantling | L5: DBD Bld | M5: Day | N5: 5 | O5: Steel Structure Works | P5: Dismantling | Q5: Dismantling | R5: _
A6: =IF(C6="","",MAX($A$1:A5)+1) -> 5 | B6: Ebin | C6: 46082 | D6: =_xlfn.XLOOKUP(Table134526_79101120212223242526[[#This Row],[Name Surname]],Manpower!$C$4:$C$1048576,Manpower!$B$4:$B$1048576,"") -> Encogroup | E6: Khundrakpam Shyamsan Singh | F6: =_xlfn.XLOOKUP(Table134526_79101120212223242526[[#This Row],[Name Surname]],Manpower!C:C,Manpower!D:D,) -> 99596058 | G6: =_xlfn.XLOOKUP(Table134526_79101120212223242526[[#This Row],[Name Surname]],Manpower!$C$4:$C$1048576,Manpower!$F$4:$F$1048576,"") -> HSE Officer | H6: =_xlfn.XLOOKUP(Table134526_79101120212223242526[[#This Row],[Name Surname]],Manpower!$C$4:$C$1048576,Manpower!$H$4:$H$1048576,"") -> Manpower | I6: =_xlfn.XLOOKUP(Table134526_79101120212223242526[[#This Row],[Name Surname]],Manpower!$C$4:$C$1048576,Manpower!$H$4:$H$1048576,"") -> Manpower | J6: Yard 3 | K6: Dismantling | L6: DBD Bld | M6: Day | N6: 8 | O6: Steel Structure Works | P6: Dismantling | Q6: Dismantling | R6: _
A7: =IF(C7="","",MAX($A$1:A6)+1) -> 6 | B7: Ebin | C7: 46082 | D7: =_xlfn.XLOOKUP(Table134526_79101120212223242526[[#This Row],[Name Surname]],Manpower!$C$4:$C$1048576,Manpower!$B$4:$B$1048576,"") -> Encogroup | E7: Lav Kansaraj | F7: =_xlfn.XLOOKUP(Table134526_79101120212223242526[[#This Row],[Name Surname]],Manpower!C:C,Manpower!D:D,) -> 140697039 | G7: =_xlfn.XLOOKUP(Table134526_79101120212223242526[[#This Row],[Name Surname]],Manpower!$C$4:$C$1048576,Manpower!$F$4:$F$1048576,"") -> Fitter/Erector | H7: =_xlfn.XLOOKUP(Table134526_79101120212223242526[[#This Row],[Name Surname]],Manpower!$C$4:$C$1048576,Manpower!$H$4:$H$1048576,"") -> Manpower | I7: =_xlfn.XLOOKUP(Table134526_79101120212223242526[[#This Row],[Name Surname]],Manpower!$C$4:$C$1048576,Manpower!$H$4:$H$1048576,"") -> Manpower | J7: Yard 3 | K7: Dismantling | L7: DBD Bld | M7: Day | N7: 8 | O7: Steel Structure Works | P7: Dismantling | Q7: Dismantling | R7: _
A8: =IF(C8="","",MAX($A$1:A7)+1) -> 7 | B8: Ebin | C8: 46082 | D8: =_xlfn.XLOOKUP(Table134526_79101120212223242526[[#This Row],[Name Surname]],Manpower!$C$4:$C$1048576,Manpower!$B$4:$B$1048576,"") -> Encogroup | E8: Rajesh Thakur | F8: =_xlfn.XLOOKUP(Table134526_79101120212223242526[[#This Row],[Name Surname]],Manpower!C:C,Manpower!D:D,) -> 124565057 | G8: =_xlfn.XLOOKUP(Table134526_79101120212223242526[[#This Row],[Name Surname]],Manpower!$C$4:$C$1048576,Manpower!$F$4:$F$1048576,"") -> Fitter/Erector | H8: =_xlfn.XLOOKUP(Table134526_79101120212223242526[[#This Row],[Name Surname]],Manpower!$C$4:$C$1048576,Manpower!$H$4:$H$1048576,"") -> Manpower | I8: =_xlfn.XLOOKUP(Table134526_79101120212223242526[[#This Row],[Name Surname]],Manpower!$C$4:$C$1048576,Manpower!$H$4:$H$1048576,"") -> Manpower | J8: Yard 3 | K8: Dismantling | L8: DBD Bld | M8: Day | N8: 8 | O8: Steel Structure Works | P8: Dismantling | Q8: Dismantling | R8: _
A9: =IF(C9="","",MAX($A$1:A8)+1) -> 8 | B9: Ebin | C9: 46082 | D9: =_xlfn.XLOOKUP(Table134526_79101120212223242526[[#This Row],[Name Surname]],Manpower!$C$4:$C$1048576,Manpower!$B$4:$B$1048576,"") -> Encogroup | E9: Pradip Rai | F9: =_xlfn.XLOOKUP(Table134526_79101120212223242526[[#This Row],[Name Surname]],Manpower!C:C,Manpower!D:D,) -> 141365023 | G9: =_xlfn.XLOOKUP(Table134526_79101120212223242526[[#This Row],[Name Surname]],Manpower!$C$4:$C$1048576,Manpower!$F$4:$F$1048576,"") -> Grinder | H9: =_xlfn.XLOOKUP(Table134526_79101120212223242526[[#This Row],[Name Surname]],Manpower!$C$4:$C$1048576,Manpower!$H$4:$H$1048576,"") -> Manpower | I9: =_xlfn.XLOOKUP(Table134526_79101120212223242526[[#This Row],[Name Surname]],Manpower!$C$4:$C$1048576,Manpower!$H$4:$H$1048576,"") -> Manpower | J9: Yard 3 | K9: Dismantling | L9: DBD Bld | M9: Day | N9: 8 | O9: Steel Structure Works | P9: Dismantling | Q9: Dismantling | R9: _ | S9: Parking Area
A10: =IF(C10="","",MAX($A$1:A9)+1) -> 9 | B10: Ebin | C10: 46082 | D10: =_xlfn.XLOOKUP(Table134526_79101120212223242526[[#This Row],[Name Surname]],Manpower!$C$4:$C$1048576,Manpower!$B$4:$B$1048576,"") -> AL Omar International TRAD AND CONT | E10: Md Tarek Hossain | F10: =_xlfn.XLOOKUP(Table134526_79101120212223242526[[#This Row],[Name Surname]],Manpower!C:C,Manpower!D:D,) -> 114929202 | G10: =_xlfn.XLOOKUP(Table134526_79101120212223242526[[#This Row],[Name Surname]],Manpower!$C$4:$C$1048576,Manpower!$F$4:$F$1048576,"") -> RIgger | H10: =_xlfn.XLOOKUP(Table134526_79101120212223242526[[#This Row],[Name Surname]],Manpower!$C$4:$C$1048576,Manpower!$H$4:$H$1048576,"") -> Sub Contactor | I10: =_xlfn.XLOOKUP(Table134526_79101120212223242526[[#This Row],[Name Surname]],Manpower!$C$4:$C$1048576,Manpower!$H$4:$H$1048576,"") -> Sub Contactor | J10: Yard 3 | K10: Dismantling | L10: DBD Bld | M10: Day | N10: 5 | O10: Steel Structure Works | P10: Dismantling | Q10: Dismantling | R10: _
A11: =IF(C11="","",MAX($A$1:A10)+1) -> 10 | B11: Ebin | C11: 46082 | D11: =_xlfn.XLOOKUP(Table134526_79101120212223242526[[#This Row],[Name Surname]],Manpower!$C$4:$C$1048576,Manpower!$B$4:$B$1048576,"") -> Encogroup | E11: Ranaanand Kumar | F11: =_xlfn.XLOOKUP(Table134526_79101120212223242526[[#This Row],[Name Surname]],Manpower!C:C,Manpower!D:D,) -> 140742088 | G11: =_xlfn.XLOOKUP(Table134526_79101120212223242526[[#This Row],[Name Surname]],Manpower!$C$4:$C$1048576,Manpower!$F$4:$F$1048576,"") -> Fitter/Erector | H11: =_xlfn.XLOOKUP(Table134526_79101120212223242526[[#This Row],[Name Surname]],Manpower!$C$4:$C$1048576,Manpower!$H$4:$H$1048576,"") -> Manpower | I11: =_xlfn.XLOOKUP(Table134526_79101120212223242526[[#This Row],[Name Surname]],Manpower!$C$4:$C$1048576,Manpower!$H$4:$H$1048576,"") -> Manpower | J11: Yard 3 | K11: Dismantling | L11: DBD Bld | M11: Day | N11: 8 | O11: Steel Structure Works | P11: Dismantling | Q11: Dismantling | R11: _
A12: =IF(C12="","",MAX($A$1:A11)+1) -> 11 | B12: Ebin | C12: 46082 | D12: =_xlfn.XLOOKUP(Table134526_79101120212223242526[[#This Row],[Name Surname]],Manpower!$C$4:$C$1048576,Manpower!$B$4:$B$1048576,"") -> Rial Al Khaleej | E12: Shahzad Latif | F12: =_xlfn.XLOOKUP(Table134526_79101120212223242526[[#This Row],[Name Surname]],Manpower!C:C,Manpower!D:D,) -> 98845403 | G12: =_xlfn.XLOOKUP(Table134526_79101120212223242526[[#This Row],[Name Surname]],Manpower!$C$4:$C$1048576,Manpower!$F$4:$F$1048576,"") -> Crane Operator-100T Zoomlion Telescopic | H12: Manpower | I12: Manpower | J12: Yard 3 | K12: Dismantling | L12: DBD Bld | M12: Day | N12: 8 | O12: Material Handling | P12: Strucutre Pre-Assembly | Q12: Material unloading by crane | R12: Crane Operator
A13: =IF(C13="","",MAX($A$1:A12)+1) -> 12 | B13: Ebin | C13: 46082 | D13: =_xlfn.XLOOKUP(Table134526_79101120212223242526[[#This Row],[Name Surname]],Manpower!$C$4:$C$1048576,Manpower!$B$4:$B$1048576,"") -> Encogroup | E13: Shyam Dhani | F13: =_xlfn.XLOOKUP(Table134526_79101120212223242526[[#This Row],[Name Surname]],Manpower!C:C,Manpower!D:D,) -> 140806218 | G13: =_xlfn.XLOOKUP(Table134526_79101120212223242526[[#This Row],[Name Surname]],Manpower!$C$4:$C$1048576,Manpower!$F$4:$F$1048576,"") -> Fitter/Erector | H13: =_xlfn.XLOOKUP(Table134526_79101120212223242526[[#This Row],[Name Surname]],Manpower!$C$4:$C$1048576,Manpower!$H$4:$H$1048576,"") -> Manpower | I13: =_xlfn.XLOOKUP(Table134526_79101120212223242526[[#This Row],[Name Surname]],Manpower!$C$4:$C$1048576,Manpower!$H$4:$H$1048576,"") -> Manpower | J13: Yard 3 | K13: Dismantling | L13: DBD Bld | M13: Day | N13: 8 | O13: Steel Structure Works | P13: Dismantling | Q13: Dismantling | R13: _ | S13: YARD 3
A14: =IF(C14="","",MAX($A$1:A13)+1) -> 13 | B14: Ebin | C14: 46082 | D14: =_xlfn.XLOOKUP(Table134526_79101120212223242526[[#This Row],[Name Surname]],Manpower!$C$4:$C$1048576,Manpower!$B$4:$B$1048576,"") -> Encogroup | E14: Verendra Kumar Hari Lal | F14: =_xlfn.XLOOKUP(Table134526_79101120212223242526[[#This Row],[Name Surname]],Manpower!C:C,Manpower!D:D,) -> 140844618 | G14: =_xlfn.XLOOKUP(Table134526_79101120212223242526[[#This Row],[Name Surname]],Manpower!$C$4:$C$1048576,Manpower!$F$4:$F$1048576,"") -> Assistant/Helper | H14: =_xlfn.XLOOKUP(Table134526_79101120212223242526[[#This Row],[Name Surname]],Manpower!$C$4:$C$1048576,Manpower!$H$4:$H$1048576,"") -> Manpower | I14: =_xlfn.XLOOKUP(Table134526_79101120212223242526[[#This Row],[Name Surname]],Manpower!$C$4:$C$1048576,Manpower!$H$4:$H$1048576,"") -> Manpower | J14: Yard 3 | K14: Dismantling | L14: DBD Bld | M14: Day | N14: 5 | O14: Steel Structure Works | P14: Dismantling | Q14: Dismantling | R14: _
A15: =IF(C15="","",MAX($A$1:A14)+1) -> 14 | B15: Ebin | C15: 46082 | D15: =_xlfn.XLOOKUP(Table134526_79101120212223242526[[#This Row],[Name Surname]],Manpower!$C$4:$C$1048576,Manpower!$B$4:$B$1048576,"") -> Bright Light | E15: 100T TELESCOPIC CRANE (RENTAL)-Sany | F15: =_xlfn.XLOOKUP(Table134526_79101120212223242526[[#This Row],[Name Surname]],Manpower!C:C,Manpower!D:D,) -> #N/A | G15: =_xlfn.XLOOKUP(Table134526_79101120212223242526[[#This Row],[Name Surname]],Manpower!$C$4:$C$1048576,Manpower!$F$4:$F$1048576,"") -> 100T Telescopic Crane | H15: Manpower | I15: Manpower | J15: Yard 2 | K15: _ | L15: CT-1010-02 | M15: Day | N15: 8 | O15: Material Handling | P15: Strucutre Pre-Assembly | Q15: Material unloading by crane | R15: Structural material segregation, offloading of materials from yard-3 to yard-2, pre-assembly&erection on temporary support installation
A16: =IF(C16="","",MAX($A$1:A15)+1) -> 15 | B16: Ebin | C16: 46082 | D16: =_xlfn.XLOOKUP(Table134526_79101120212223242526[[#This Row],[Name Surname]],Manpower!$C$4:$C$1048576,Manpower!$B$4:$B$1048576,"") -> Bright Light | E16: 150T CRAWLER CRANE (RENTAL)-Sany | F16: =_xlfn.XLOOKUP(Table134526_79101120212223242526[[#This Row],[Name Surname]],Manpower!C:C,Manpower!D:D,) -> #N/A | G16: =_xlfn.XLOOKUP(Table134526_79101120212223242526[[#This Row],[Name Surname]],Manpower!$C$4:$C$1048576,Manpower!$F$4:$F$1048576,"") -> 150T-Crawler Crane | H16: =_xlfn.XLOOKUP(Table134526_79101120212223242526[[#This Row],[Name Surname]],Manpower!$C$4:$C$1048576,Manpower!$H$4:$H$1048576,"") -> Equipment | I16: =_xlfn.XLOOKUP(Table134526_79101120212223242526[[#This Row],[Name Surname]],Manpower!$C$4:$C$1048576,Manpower!$H$4:$H$1048576,"") -> Equipment | J16: Yard 2 | K16: _ | L16: CT-1010-02 | M16: Day | N16: 8 | O16: Material Handling | P16: Strucutre Pre-Assembly | Q16: Material unloading by crane | R16: 150T crawler crane handed over to Bashaer Projects for their own work for the day
A17: =IF(C17="","",MAX($A$1:A16)+1) -> 16 | B17: Ebin | C17: 46082 | D17: =_xlfn.XLOOKUP(Table134526_79101120212223242526[[#This Row],[Name Surname]],Manpower!$C$4:$C$1048576,Manpower!$B$4:$B$1048576,"") -> Encogroup | E17: 22M LCMG MANLIFT | F17: =_xlfn.XLOOKUP(Table134526_79101120212223242526[[#This Row],[Name Surname]],Manpower!C:C,Manpower!D:D,) -> #N/A | G17: =_xlfn.XLOOKUP(Table134526_79101120212223242526[[#This Row],[Name Surname]],Manpower!$C$4:$C$1048576,Manpower!$F$4:$F$1048576,"") -> 22M-Manlift | H17: =_xlfn.XLOOKUP(Table134526_79101120212223242526[[#This Row],[Name Surname]],Manpower!$C$4:$C$1048576,Manpower!$H$4:$H$1048576,"") -> Equipment | I17: =_xlfn.XLOOKUP(Table134526_79101120212223242526[[#This Row],[Name Surname]],Manpower!$C$4:$C$1048576,Manpower!$H$4:$H$1048576,"") -> Equipment | J17: Yard 2 | K17: _ | L17: CT-1010-02 | M17: Day | N17: 8 | O17: Steel Structure Works | P17: Strucutre Pre-Assembly | Q17: Strucutre Pre-Assembly | R17: Structural material segregation, offloading of materials from yard-3 to yard-2, pre-assembly&erection on temporary support installation
A18: =IF(C18="","",MAX($A$1:A17)+1) -> 17 | B18: Ebin | C18: 46082 | D18: =_xlfn.XLOOKUP(Table134526_79101120212223242526[[#This Row],[Name Surname]],Manpower!$C$4:$C$1048576,Manpower!$B$4:$B$1048576,"") -> Encogroup | E18: 28M LCMG MANLIFT | F18: =_xlfn.XLOOKUP(Table134526_79101120212223242526[[#This Row],[Name Surname]],Manpower!C:C,Manpower!D:D,) -> #N/A | G18: =_xlfn.XLOOKUP(Table134526_79101120212223242526[[#This Row],[Name Surname]],Manpower!$C$4:$C$1048576,Manpower!$F$4:$F$1048576,"") -> 28M-Manlift | H18: =_xlfn.XLOOKUP(Table134526_79101120212223242526[[#This Row],[Name Surname]],Manpower!$C$4:$C$1048576,Manpower!$H$4:$H$1048576,"") -> Equipment | I18: =_xlfn.XLOOKUP(Table134526_79101120212223242526[[#This Row],[Name Surname]],Manpower!$C$4:$C$1048576,Manpower!$H$4:$H$1048576,"") -> Equipment | J18: Yard 2 | K18: _ | L18: CT-1010-02 | M18: Idle | N18: 8 | O18: Steel Structure Works | P18: Strucutre Pre-Assembly | Q18: Strucutre Pre-Assembly | R18: No usage
A19: =IF(C19="","",MAX($A$1:A18)+1) -> 18 | B19: Ebin | C19: 46082 | D19: =_xlfn.XLOOKUP(Table134526_79101120212223242526[[#This Row],[Name Surname]],Manpower!$C$4:$C$1048576,Manpower!$B$4:$B$1048576,"") -> Encogroup | E19: Ebin Ben | F19: =_xlfn.XLOOKUP(Table134526_79101120212223242526[[#This Row],[Name Surname]],Manpower!C:C,Manpower!D:D,) -> 116589569 | G19: =_xlfn.XLOOKUP(Table134526_79101120212223242526[[#This Row],[Name Surname]],Manpower!$C$4:$C$1048576,Manpower!$F$4:$F$1048576,"") -> Mechanical Engineer | H19: =_xlfn.XLOOKUP(Table134526_79101120212223242526[[#This Row],[Name Surname]],Manpower!$C$4:$C$1048576,Manpower!$H$4:$H$1048576,"") -> Manpower | I19: =_xlfn.XLOOKUP(Table134526_79101120212223242526[[#This Row],[Name Surname]],Manpower!$C$4:$C$1048576,Manpower!$H$4:$H$1048576,"") -> Manpower | J19: Yard 2 | K19: _ | L19: CT-1010-02 | M19: Idle | N19: 5 | O19: Steel Structure Works | P19: Strucutre Pre-Assembly | Q19: Strucutre Pre-Assembly | R19: Structural material segregation, offloading of materials from yard-3 to yard-2, pre-assembly&erection on temporary support installation
A20: =IF(C20="","",MAX($A$1:A18)+1) -> 18 | B20: Ebin | C20: 46082 | D20: =_xlfn.XLOOKUP(Table134526_79101120212223242526[[#This Row],[Name Surname]],Manpower!$C$4:$C$1048576,Manpower!$B$4:$B$1048576,"") -> Encogroup | E20: Ajithkumar Aravindakshanpillai | F20: =_xlfn.XLOOKUP(Table134526_79101120212223242526[[#This Row],[Name Surname]],Manpower!C:C,Manpower!D:D,) -> 140693697 | G20: =_xlfn.XLOOKUP(Table134526_79101120212223242526[[#This Row],[Name Surname]],Manpower!$C$4:$C$1048576,Manpower!$F$4:$F$1048576,"") -> HSE Officer | H20: =_xlfn.XLOOKUP(Table134526_79101120212223242526[[#This Row],[Name Surname]],Manpower!$C$4:$C$1048576,Manpower!$H$4:$H$1048576,"") -> Manpower | I20: =_xlfn.XLOOKUP(Table134526_79101120212223242526[[#This Row],[Name Surname]],Manpower!$C$4:$C$1048576,Manpower!$H$4:$H$1048576,"") -> Manpower | J20: Yard 2 | K20: _ | L20: CT-1010-02 | M20: Day | N20: 10 | O20: Steel Structure Works | P20: Strucutre Pre-Assembly | Q20: Strucutre Pre-Assembly | R20: Structural material segregation, offloading of materials from yard-3 to yard-2, pre-assembly&erection on temporary support installation
A21: =IF(C21="","",MAX($A$1:A20)+1) -> 19 | B21: Ebin | C21: 46082 | D21: =_xlfn.XLOOKUP(Table134526_79101120212223242526[[#This Row],[Name Surname]],Manpower!$C$4:$C$1048576,Manpower!$B$4:$B$1048576,"") -> Encogroup | E21: Ashwini Kumar | F21: =_xlfn.XLOOKUP(Table134526_79101120212223242526[[#This Row],[Name Surname]],Manpower!C:C,Manpower!D:D,) -> 127414586 | G21: =_xlfn.XLOOKUP(Table134526_79101120212223242526[[#This Row],[Name Surname]],Manpower!$C$4:$C$1048576,Manpower!$F$4:$F$1048576,"") -> Electrician | H21: =_xlfn.XLOOKUP(Table134526_79101120212223242526[[#This Row],[Name Surname]],Manpower!$C$4:$C$1048576,Manpower!$H$4:$H$1048576,"") -> Manpower | I21: =_xlfn.XLOOKUP(Table134526_79101120212223242526[[#This Row],[Name Surname]],Manpower!$C$4:$C$1048576,Manpower!$H$4:$H$1048576,"") -> Manpower | J21: Yard 2 | K21: _ | L21: CT-1010-02 | M21: Day | N21: 5 | O21: Electrical Works | P21: Strucutre Pre-Assembly | Q21: Electrical testing | R21: Structural material segregation, offloading of materials from yard-3 to yard-2, pre-assembly&erection on temporary support installation
A22: =IF(C22="","",MAX($A$1:A21)+1) -> 20 | B22: Ebin | C22: 46082 | D22: =_xlfn.XLOOKUP(Table134526_79101120212223242526[[#This Row],[Name Surname]],Manpower!$C$4:$C$1048576,Manpower!$B$4:$B$1048576,"") -> Encogroup | E22: Clyde Abrazaldo | F22: =_xlfn.XLOOKUP(Table134526_79101120212223242526[[#This Row],[Name Surname]],Manpower!C:C,Manpower!D:D,) -> 141169085 | G22: =_xlfn.XLOOKUP(Table134526_79101120212223242526[[#This Row],[Name Surname]],Manpower!$C$4:$C$1048576,Manpower!$F$4:$F$1048576,"") -> Welder | H22: =_xlfn.XLOOKUP(Table134526_79101120212223242526[[#This Row],[Name Surname]],Manpower!$C$4:$C$1048576,Manpower!$H$4:$H$1048576,"") -> Manpower | I22: =_xlfn.XLOOKUP(Table134526_79101120212223242526[[#This Row],[Name Surname]],Manpower!$C$4:$C$1048576,Manpower!$H$4:$H$1048576,"") -> Manpower | J22: Yard 2 | K22: _ | L22: CT-1010-02 | M22: Day | N22: 8 | O22: Steel Structure Works | P22: Ground pre-assembly | Q22: Ground pre-assembly | R22: Structural material segregation, offloading of materials from yard-3 to yard-2, pre-assembly&erection on temporary support installation | S22: YARD 3
A23: =IF(C23="","",MAX($A$1:A22)+1) -> 21 | B23: Ebin | C23: 46082 | D23: =_xlfn.XLOOKUP(Table134526_79101120212223242526[[#This Row],[Name Surname]],Manpower!$C$4:$C$1048576,Manpower!$B$4:$B$1048576,"") -> Encogroup | E23: Daniel Jr Mosiquira | F23: =_xlfn.XLOOKUP(Table134526_79101120212223242526[[#This Row],[Name Surname]],Manpower!C:C,Manpower!D:D,) -> 141169047 | G23: =_xlfn.XLOOKUP(Table134526_79101120212223242526[[#This Row],[Name Surname]],Manpower!$C$4:$C$1048576,Manpower!$F$4:$F$1048576,"") -> Welder | H23: =_xlfn.XLOOKUP(Table134526_79101120212223242526[[#This Row],[Name Surname]],Manpower!$C$4:$C$1048576,Manpower!$H$4:$H$1048576,"") -> Manpower | I23: =_xlfn.XLOOKUP(Table134526_79101120212223242526[[#This Row],[Name Surname]],Manpower!$C$4:$C$1048576,Manpower!$H$4:$H$1048576,"") -> Manpower | J23: Yard 2 | K23: _ | L23: CT-1010-02 | M23: Day | N23: 8 | O23: Steel Structure Works | P23: Ground pre-assembly | Q23: Ground pre-assembly | R23: Structural material segregation, offloading of materials from yard-3 to yard-2, pre-assembly&erection on temporary support installation | S23: YARD 3
A24: =IF(C24="","",MAX($A$1:A23)+1) -> 22 | B24: Ebin | C24: 46082 | D24: =_xlfn.XLOOKUP(Table134526_79101120212223242526[[#This Row],[Name Surname]],Manpower!$C$4:$C$1048576,Manpower!$B$4:$B$1048576,"") -> Encogroup | E24: Dharmvir Upadhyay | F24: =_xlfn.XLOOKUP(Table134526_79101120212223242526[[#This Row],[Name Surname]],Manpower!C:C,Manpower!D:D,) -> 140844797 | G24: =_xlfn.XLOOKUP(Table134526_79101120212223242526[[#This Row],[Name Surname]],Manpower!$C$4:$C$1048576,Manpower!$F$4:$F$1048576,"") -> Fitter/Erector | H24: =_xlfn.XLOOKUP(Table134526_79101120212223242526[[#This Row],[Name Surname]],Manpower!$C$4:$C$1048576,Manpower!$H$4:$H$1048576,"") -> Manpower | I24: =_xlfn.XLOOKUP(Table134526_79101120212223242526[[#This Row],[Name Surname]],Manpower!$C$4:$C$1048576,Manpower!$H$4:$H$1048576,"") -> Manpower | J24: Yard 2 | K24: _ | L24: CT-1010-02 | M24: Day | N24: 8 | O24: Steel Structure Works | P24: Strucutre Pre-Assembly | Q24: Ground pre-assembly | R24: Structural material segregation, offloading of materials from yard-3 to yard-2, pre-assembly&erection on temporary support installation
A25: =IF(C25="","",MAX($A$1:A24)+1) -> 23 | B25: Ebin | C25: 46082 | D25: =_xlfn.XLOOKUP(Table134526_79101120212223242526[[#This Row],[Name Surname]],Manpower!$C$4:$C$1048576,Manpower!$B$4:$B$1048576,"") -> Encogroup | E25: 22KVA GENERATOR | F25: =_xlfn.XLOOKUP(Table134526_79101120212223242526[[#This Row],[Name Surname]],Manpower!C:C,Manpower!D:D,) -> #N/A | G25: =_xlfn.XLOOKUP(Table134526_79101120212223242526[[#This Row],[Name Surname]],Manpower!$C$4:$C$1048576,Manpower!$F$4:$F$1048576,"") -> 22KVA-Generator | H25: =_xlfn.XLOOKUP(Table134526_79101120212223242526[[#This Row],[Name Surname]],Manpower!$C$4:$C$1048576,Manpower!$H$4:$H$1048576,"") -> Equipment | I25: =_xlfn.XLOOKUP(Table134526_79101120212223242526[[#This Row],[Name Surname]],Manpower!$C$4:$C$1048576,Manpower!$H$4:$H$1048576,"") -> Equipment | J25: Yard 2 | K25: _ | L25: CT-1010-02 | M25: Day | N25: 8 | O25: Steel Structure Works | P25: Strucutre Pre-Assembly | Q25: Strucutre Pre-Assembly | R25: Structural material segregation, offloading of materials from yard-3 to yard-2, pre-assembly&erection on temporary support installation
A26: =IF(C26="","",MAX($A$1:A24)+1) -> 23 | B26: Ebin | C26: 46082 | D26: =_xlfn.XLOOKUP(Table134526_79101120212223242526[[#This Row],[Name Surname]],Manpower!$C$4:$C$1048576,Manpower!$B$4:$B$1048576,"") -> Bright Light | E26: Gurtirath Singh | F26: =_xlfn.XLOOKUP(Table134526_79101120212223242526[[#This Row],[Name Surname]],Manpower!C:C,Manpower!D:D,) -> 114531608 | G26: =_xlfn.XLOOKUP(Table134526_79101120212223242526[[#This Row],[Name Surname]],Manpower!$C$4:$C$1048576,Manpower!$F$4:$F$1048576,"") -> Crane Operator-150T Sany Crawler | H26: =_xlfn.XLOOKUP(Table134526_79101120212223242526[[#This Row],[Name Surname]],Manpower!$C$4:$C$1048576,Manpower!$H$4:$H$1048576,"") -> Manpower | I26: =_xlfn.XLOOKUP(Table134526_79101120212223242526[[#This Row],[Name Surname]],Manpower!$C$4:$C$1048576,Manpower!$H$4:$H$1048576,"") -> Manpower | J26: Yard 2 | K26: _ | L26: CT-1010-02 | M26: Day | N26: 8 | O26: Material Handling | P26: Strucutre Pre-Assembly | Q26: Material unloading by crane | R26: Structural material segregation, offloading of materials from yard-3 to yard-2, pre-assembly&erection on temporary support installation
A27: =IF(C27="","",MAX($A$1:A26)+1) -> 24 | B27: Ebin | C27: 46082 | D27: =_xlfn.XLOOKUP(Table134526_79101120212223242526[[#This Row],[Name Surname]],Manpower!$C$4:$C$1048576,Manpower!$B$4:$B$1048576,"") -> AL Saif & Al QALLM ENT LLC | E27: MD Ayub Ali | F27: =_xlfn.XLOOKUP(Table134526_79101120212223242526[[#This Row],[Name Surname]],Manpower!C:C,Manpower!D:D,) -> 108478006 | G27: =_xlfn.XLOOKUP(Table134526_79101120212223242526[[#This Row],[Name Surname]],Manpower!$C$4:$C$1048576,Manpower!$F$4:$F$1048576,"") -> RIgger | H27: =_xlfn.XLOOKUP(Table134526_79101120212223242526[[#This Row],[Name Surname]],Manpower!$C$4:$C$1048576,Manpower!$H$4:$H$1048576,"") -> Sub Contactor | I27: =_xlfn.XLOOKUP(Table134526_79101120212223242526[[#This Row],[Name Surname]],Manpower!$C$4:$C$1048576,Manpower!$H$4:$H$1048576,"") -> Sub Contactor | J27: Yard 2 | K27: _ | L27: CT-1010-02 | M27: Day | N27: 8 | O27: Steel Structure Works | P27: Strucutre Pre-Assembly | Q27: Strucutre Pre-Assembly | R27: Structural material segregation, offloading of materials from yard-3 to yard-2, pre-assembly&erection on temporary support installation
A28: =IF(C28="","",MAX($A$1:A27)+1) -> 25 | B28: Ebin | C28: 46082 | D28: =_xlfn.XLOOKUP(Table134526_79101120212223242526[[#This Row],[Name Surname]],Manpower!$C$4:$C$1048576,Manpower!$B$4:$B$1048576,"") -> AL Omar International TRAD AND CONT | E28: Md Hasan Howlader | F28: =_xlfn.XLOOKUP(Table134526_79101120212223242526[[#This Row],[Name Surname]],Manpower!C:C,Manpower!D:D,) -> 115018512 | G28: =_xlfn.XLOOKUP(Table134526_79101120212223242526[[#This Row],[Name Surname]],Manpower!$C$4:$C$1048576,Manpower!$F$4:$F$1048576,"") -> RIgger | H28: =_xlfn.XLOOKUP(Table134526_79101120212223242526[[#This Row],[Name Surname]],Manpower!$C$4:$C$1048576,Manpower!$H$4:$H$1048576,"") -> Sub Contactor | I28: =_xlfn.XLOOKUP(Table134526_79101120212223242526[[#This Row],[Name Surname]],Manpower!$C$4:$C$1048576,Manpower!$H$4:$H$1048576,"") -> Sub Contactor | J28: Yard 2 | K28: _ | L28: CT-1010-02 | M28: Day | N28: 8 | O28: Steel Structure Works | P28: Strucutre Pre-Assembly | Q28: Ground pre-assembly | R28: Structural material segregation, offloading of materials from yard-3 to yard-2, pre-assembly&erection on temporary support installation
A29: =IF(C29="","",MAX($A$1:A28)+1) -> 26 | B29: Ebin | C29: 46082 | D29: =_xlfn.XLOOKUP(Table134526_79101120212223242526[[#This Row],[Name Surname]],Manpower!$C$4:$C$1048576,Manpower!$B$4:$B$1048576,"") -> Encogroup | E29: Pappu Kumar Yadaw | F29: =_xlfn.XLOOKUP(Table134526_79101120212223242526[[#This Row],[Name Surname]],Manpower!C:C,Manpower!D:D,) -> 122082769 | G29: =_xlfn.XLOOKUP(Table134526_79101120212223242526[[#This Row],[Name Surname]],Manpower!$C$4:$C$1048576,Manpower!$F$4:$F$1048576,"") -> Grinder | H29: =_xlfn.XLOOKUP(Table134526_79101120212223242526[[#This Row],[Name Surname]],Manpower!$C$4:$C$1048576,Manpower!$H$4:$H$1048576,"") -> Manpower | I29: =_xlfn.XLOOKUP(Table134526_79101120212223242526[[#This Row],[Name Surname]],Manpower!$C$4:$C$1048576,Manpower!$H$4:$H$1048576,"") -> Manpower | J29: Yard 2 | K29: _ | L29: CT-1010-02 | M29: Day | N29: 8 | O29: Steel Structure Works | P29: Strucutre Pre-Assembly | Q29: Ground pre-assembly | R29: Structural material segregation, offloading of materials from yard-3 to yard-2, pre-assembly&erection on temporary support installation
A30: =IF(C30="","",MAX($A$1:A29)+1) -> 27 | B30: Ebin | C30: 46082 | D30: =_xlfn.XLOOKUP(Table134526_79101120212223242526[[#This Row],[Name Surname]],Manpower!$C$4:$C$1048576,Manpower!$B$4:$B$1048576,"") -> Encogroup | E30: Rabih Rifai | F30: =_xlfn.XLOOKUP(Table134526_79101120212223242526[[#This Row],[Name Surname]],Manpower!C:C,Manpower!D:D,) -> 116915582 | G30: =_xlfn.XLOOKUP(Table134526_79101120212223242526[[#This Row],[Name Surname]],Manpower!$C$4:$C$1048576,Manpower!$F$4:$F$1048576,"") -> Mechanical Superintendent | H30: =_xlfn.XLOOKUP(Table134526_79101120212223242526[[#This Row],[Name Surname]],Manpower!$C$4:$C$1048576,Manpower!$H$4:$H$1048576,"") -> Manpower | I30: =_xlfn.XLOOKUP(Table134526_79101120212223242526[[#This Row],[Name Surname]],Manpower!$C$4:$C$1048576,Manpower!$H$4:$H$1048576,"") -> Manpower | J30: Yard 2 | K30: _ | L30: CT-1010-02 | M30: Day | N30: 6 | O30: Steel Structure Works | P30: Strucutre Pre-Assembly | Q30: Ground pre-assembly | R30: Structural material segregation, offloading of materials from yard-3 to yard-2, pre-assembly&erection on temporary support installation
A31: =IF(C31="","",MAX($A$1:A30)+1) -> 28 | B31: Ebin | C31: 46082 | D31: =_xlfn.XLOOKUP(Table134526_79101120212223242526[[#This Row],[Name Surname]],Manpower!$C$4:$C$1048576,Manpower!$B$4:$B$1048576,"") -> Encogroup | E31: Rogie Jr Mabilog | F31: =_xlfn.XLOOKUP(Table134526_79101120212223242526[[#This Row],[Name Surname]],Manpower!C:C,Manpower!D:D,) -> 141169071 | G31: =_xlfn.XLOOKUP(Table134526_79101120212223242526[[#This Row],[Name Surname]],Manpower!$C$4:$C$1048576,Manpower!$F$4:$F$1048576,"") -> Welding Supervisor | H31: =_xlfn.XLOOKUP(Table134526_79101120212223242526[[#This Row],[Name Surname]],Manpower!$C$4:$C$1048576,Manpower!$H$4:$H$1048576,"") -> Manpower | I31: =_xlfn.XLOOKUP(Table134526_79101120212223242526[[#This Row],[Name Surname]],Manpower!$C$4:$C$1048576,Manpower!$H$4:$H$1048576,"") -> Manpower | J31: Yard 2 | K31: _ | L31: CT-1010-02 | M31: Day | N31: 8 | O31: Steel Structure Works | P31: Strucutre Pre-Assembly | Q31: Ground pre-assembly | R31: Structural material segregation, offloading of materials from yard-3 to yard-2, pre-assembly&erection on temporary support installation
A32: =IF(C32="","",MAX($A$1:A31)+1) -> 29 | B32: Ebin | C32: 46082 | D32: =_xlfn.XLOOKUP(Table134526_79101120212223242526[[#This Row],[Name Surname]],Manpower!$C$4:$C$1048576,Manpower!$B$4:$B$1048576,"") -> Encogroup | E32: Shivam Yadhav | F32: =_xlfn.XLOOKUP(Table134526_79101120212223242526[[#This Row],[Name Surname]],Manpower!C:C,Manpower!D:D,) -> 141365126 | G32: =_xlfn.XLOOKUP(Table134526_79101120212223242526[[#This Row],[Name Surname]],Manpower!$C$4:$C$1048576,Manpower!$F$4:$F$1048576,"") -> Helper | H32: =_xlfn.XLOOKUP(Table134526_79101120212223242526[[#This Row],[Name Surname]],Manpower!$C$4:$C$1048576,Manpower!$H$4:$H$1048576,"") -> Manpower | I32: =_xlfn.XLOOKUP(Table134526_79101120212223242526[[#This Row],[Name Surname]],Manpower!$C$4:$C$1048576,Manpower!$H$4:$H$1048576,"") -> Manpower | J32: Yard 2 | K32: _ | L32: CT-1010-02 | M32: Day | N32: 8 | O32: Steel Structure Works | P32: Strucutre Pre-Assembly | Q32: Ground pre-assembly | R32: Structural material segregation, offloading of materials from yard-3 to yard-2, pre-assembly&erection on temporary support installation
A33: =IF(C33="","",MAX($A$1:A32)+1) -> 30 | B33: Ebin | C33: 46082 | D33: =_xlfn.XLOOKUP(Table134526_79101120212223242526[[#This Row],[Name Surname]],Manpower!$C$4:$C$1048576,Manpower!$B$4:$B$1048576,"") -> Bright Light | E33: Siyaram Yadav | F33: =_xlfn.XLOOKUP(Table134526_79101120212223242526[[#This Row],[Name Surname]],Manpower!C:C,Manpower!D:D,) -> 81379273 | G33: =_xlfn.XLOOKUP(Table134526_79101120212223242526[[#This Row],[Name Surname]],Manpower!$C$4:$C$1048576,Manpower!$F$4:$F$1048576,"") -> Crane Operator-100T Sany Telescopic | H33: Manpower | I33: =_xlfn.XLOOKUP(Table134526_79101120212223242526[[#This Row],[Name Surname]],Manpower!$C$4:$C$1048576,Manpower!$H$4:$H$1048576,"") -> Manpower | J33: Yard 2 | K33: _ | L33: CT-1010-02 | M33: Day | N33: 8 | O33: Material Handling | P33: Strucutre Pre-Assembly | Q33: Material unloading by crane | R33: Structural material segregation, offloading of materials from yard-3 to yard-2, pre-assembly&erection on temporary support installation
A34: =IF(C34="","",MAX($A$1:A33)+1) -> 31 | B34: Ebin | C34: 46082 | D34: =_xlfn.XLOOKUP(Table134526_79101120212223242526[[#This Row],[Name Surname]],Manpower!$C$4:$C$1048576,Manpower!$B$4:$B$1048576,"") -> Encogroup | E34: Sonu Kumar Pandey | F34: =_xlfn.XLOOKUP(Table134526_79101120212223242526[[#This Row],[Name Surname]],Manpower!C:C,Manpower!D:D,) -> 140764706 | G34: =_xlfn.XLOOKUP(Table134526_79101120212223242526[[#This Row],[Name Surname]],Manpower!$C$4:$C$1048576,Manpower!$F$4:$F$1048576,"") -> Rigger | H34: =_xlfn.XLOOKUP(Table134526_79101120212223242526[[#This Row],[Name Surname]],Manpower!$C$4:$C$1048576,Manpower!$H$4:$H$1048576,"") -> Manpower | I34: =_xlfn.XLOOKUP(Table134526_79101120212223242526[[#This Row],[Name Surname]],Manpower!$C$4:$C$1048576,Manpower!$H$4:$H$1048576,"") -> Manpower | J34: Yard 2 | K34: _ | L34: CT-1010-02 | M34: Day | N34: 8 | O34: Steel Structure Works | P34: Strucutre Pre-Assembly | Q34: Ground pre-assembly | R34: Structural material segregation, offloading of materials from yard-3 to yard-2, pre-assembly&erection on temporary support installation
A35: =IF(C35="","",MAX($A$1:A34)+1) -> 32 | B35: Ebin | C35: 46082 | D35: =_xlfn.XLOOKUP(Table134526_79101120212223242526[[#This Row],[Name Surname]],Manpower!$C$4:$C$1048576,Manpower!$B$4:$B$1048576,"") -> Encogroup | E35: Tamoor Ali Khan | F35: =_xlfn.XLOOKUP(Table134526_79101120212223242526[[#This Row],[Name Surname]],Manpower!C:C,Manpower!D:D,) -> 135325259 | G35: =_xlfn.XLOOKUP(Table134526_79101120212223242526[[#This Row],[Name Surname]],Manpower!$C$4:$C$1048576,Manpower!$F$4:$F$1048576,"") -> Permit Receiver | H35: =_xlfn.XLOOKUP(Table134526_79101120212223242526[[#This Row],[Name Surname]],Manpower!$C$4:$C$1048576,Manpower!$H$4:$H$1048576,"") -> Manpower | I35: =_xlfn.XLOOKUP(Table134526_79101120212223242526[[#This Row],[Name Surname]],Manpower!$C$4:$C$1048576,Manpower!$H$4:$H$1048576,"") -> Manpower | J35: Yard 2 | K35: _ | L35: CT-1010-02 | M35: Day | N35: 8 | O35: Steel Structure Works | P35: Strucutre Pre-Assembly | Q35: Ground pre-assembly | R35: Structural material segregation, offloading of materials from yard-3 to yard-2, pre-assembly&erection on temporary support installation
A36: =IF(C36="","",MAX($A$1:A35)+1) -> 33 | B36: Ebin | C36: 46082 | D36: =_xlfn.XLOOKUP(Table134526_79101120212223242526[[#This Row],[Name Surname]],Manpower!$C$4:$C$1048576,Manpower!$B$4:$B$1048576,"") -> Encogroup | E36: Tej Pradap Sharma | F36: =_xlfn.XLOOKUP(Table134526_79101120212223242526[[#This Row],[Name Surname]],Manpower!C:C,Manpower!D:D,) -> 141365089 | G36: =_xlfn.XLOOKUP(Table134526_79101120212223242526[[#This Row],[Name Surname]],Manpower!$C$4:$C$1048576,Manpower!$F$4:$F$1048576,"") -> Fitter | H36: =_xlfn.XLOOKUP(Table134526_79101120212223242526[[#This Row],[Name Surname]],Manpower!$C$4:$C$1048576,Manpower!$H$4:$H$1048576,"") -> Manpower | I36: =_xlfn.XLOOKUP(Table134526_79101120212223242526[[#This Row],[Name Surname]],Manpower!$C$4:$C$1048576,Manpower!$H$4:$H$1048576,"") -> Manpower | J36: Yard 2 | K36: _ | L36: CT-1010-02 | M36: Day | N36: 8 | O36: Steel Structure Works | P36: Strucutre Pre-Assembly | Q36: Ground pre-assembly | R36: Structural material segregation, offloading of materials from yard-3 to yard-2, pre-assembly&erection on temporary support installation
A37: =IF(C37="","",MAX($A$1:A36)+1) -> 34 | B37: Ebin | C37: 46082 | D37: =_xlfn.XLOOKUP(Table134526_79101120212223242526[[#This Row],[Name Surname]],Manpower!$C$4:$C$1048576,Manpower!$B$4:$B$1048576,"") -> Encogroup | E37: Vinay Chaudhary | F37: =_xlfn.XLOOKUP(Table134526_79101120212223242526[[#This Row],[Name Surname]],Manpower!C:C,Manpower!D:D,) -> 122179604 | G37: =_xlfn.XLOOKUP(Table134526_79101120212223242526[[#This Row],[Name Surname]],Manpower!$C$4:$C$1048576,Manpower!$F$4:$F$1048576,"") -> Fitter/Erector | H37: =_xlfn.XLOOKUP(Table134526_79101120212223242526[[#This Row],[Name Surname]],Manpower!$C$4:$C$1048576,Manpower!$H$4:$H$1048576,"") -> Manpower | I37: =_xlfn.XLOOKUP(Table134526_79101120212223242526[[#This Row],[Name Surname]],Manpower!$C$4:$C$1048576,Manpower!$H$4:$H$1048576,"") -> Manpower | J37: Yard 2 | K37: _ | L37: CT-1010-02 | M37: Day | N37: 8 | O37: Steel Structure Works | P37: Strucutre Pre-Assembly | Q37: Ground pre-assembly | R37: Structural material segregation, offloading of materials from yard-3 to yard-2, pre-assembly&erection on temporary support installation
A38: =IF(C38="","",MAX($A$1:A37)+1) -> 35 | B38: Ebin | C38: 46082 | D38: =_xlfn.XLOOKUP(Table134526_79101120212223242526[[#This Row],[Name Surname]],Manpower!$C$4:$C$1048576,Manpower!$B$4:$B$1048576,"") -> Encogroup | E38: Arunkumar Surendran | F38: =_xlfn.XLOOKUP(Table134526_79101120212223242526[[#This Row],[Name Surname]],Manpower!C:C,Manpower!D:D,) -> 127859069 | G38: =_xlfn.XLOOKUP(Table134526_79101120212223242526[[#This Row],[Name Surname]],Manpower!$C$4:$C$1048576,Manpower!$F$4:$F$1048576,"") -> QC Mechanical Engineer | H38: =_xlfn.XLOOKUP(Table134526_79101120212223242526[[#This Row],[Name Surname]],Manpower!$C$4:$C$1048576,Manpower!$H$4:$H$1048576,"") -> Manpower | I38: =_xlfn.XLOOKUP(Table134526_79101120212223242526[[#This Row],[Name Surname]],Manpower!$C$4:$C$1048576,Manpower!$H$4:$H$1048576,"") -> Manpower | J38: Yard 2 | K38: _ | L38: CT-1010-02 | M38: Day | N38: 10 | O38: Steel Structure Works | P38: Strucutre Pre-Assembly | Q38: Torque tightening | R38: Structural material segregation, offloading of materials from yard-3 to yard-2, pre-assembly&erection on temporary support installation
A39: =IF(C39="","",MAX($A$1:A37)+1) -> 35 | B39: Ebin | C39: 46082 | D39: =_xlfn.XLOOKUP(Table134526_79101120212223242526[[#This Row],[Name Surname]],Manpower!$C$4:$C$1048576,Manpower!$B$4:$B$1048576,"") -> Encogroup | E39: Verendra Kumar Hari Lal | F39: =_xlfn.XLOOKUP(Table134526_79101120212223242526[[#This Row],[Name Surname]],Manpower!C:C,Manpower!D:D,) -> 140844618 | G39: =_xlfn.XLOOKUP(Table134526_79101120212223242526[[#This Row],[Name Surname]],Manpower!$C$4:$C$1048576,Manpower!$F$4:$F$1048576,"") -> Assistant/Helper | H39: =_xlfn.XLOOKUP(Table134526_79101120212223242526[[#This Row],[Name Surname]],Manpower!$C$4:$C$1048576,Manpower!$H$4:$H$1048576,"") -> Manpower | I39: =_xlfn.XLOOKUP(Table134526_79101120212223242526[[#This Row],[Name Surname]],Manpower!$C$4:$C$1048576,Manpower!$H$4:$H$1048576,"") -> Manpower | J39: Yard 2 | K39: _ | L39: CT-1010-02 | M39: Day | N39: 3 | O39: Steel Structure Works | P39: Strucutre Pre-Assembly | Q39: Ground pre-assembly | R39: Structural material segregation, offloading of materials from yard-3 to yard-2, pre-assembly&erection on temporary support installation
A40: =IF(C40="","",MAX($A$1:A37)+1) -> 35 | B40: Ebin | C40: 46082 | D40: =_xlfn.XLOOKUP(Table134526_79101120212223242526[[#This Row],[Name Surname]],Manpower!$C$4:$C$1048576,Manpower!$B$4:$B$1048576,"") -> AL Omar International TRAD AND CONT | E40: Md Tarek Hossain | F40: =_xlfn.XLOOKUP(Table134526_79101120212223242526[[#This Row],[Name Surname]],Manpower!C:C,Manpower!D:D,) -> 114929202 | G40: =_xlfn.XLOOKUP(Table134526_79101120212223242526[[#This Row],[Name Surname]],Manpower!$C$4:$C$1048576,Manpower!$F$4:$F$1048576,"") -> RIgger | H40: =_xlfn.XLOOKUP(Table134526_79101120212223242526[[#This Row],[Name Surname]],Manpower!$C$4:$C$1048576,Manpower!$H$4:$H$1048576,"") -> Sub Contactor | I40: =_xlfn.XLOOKUP(Table134526_79101120212223242526[[#This Row],[Name Surname]],Manpower!$C$4:$C$1048576,Manpower!$H$4:$H$1048576,"") -> Sub Contactor | J40: Yard 2 | K40: _ | L40: CT-1010-02 | M40: Day | N40: 3 | O40: Steel Structure Works | P40: Strucutre Pre-Assembly | Q40: Ground pre-assembly | R40: Structural material segregation, offloading of materials from yard-3 to yard-2, pre-assembly&erection on temporary support installation
...

Sheet Tasks
A1: Mobilization Preparation | B1: Mobilization Preparation | C1: Material Handling & Segregation | D1: Steel Structure Works | F1: Grouting Works | G1: Piping Works | H1: Electrical Works | I1: Instrumentation Works | J1: Painting Coating | K1: Finalization | M1: Working Area | N1: Item Tag
A2: Material Handling | B2: Site access preparation | C2: Material unloading by crane | D2: Ground pre-assembly | E2: Strucutre Pre-Assembly | F2: Foundation surface cleaning | G2: Pipe rack support installation | H2: Cable tray support installation | I2: Instrument support installation | J2: Surface cleaning | K2: Final inspection | M2: Yard 2 | N2: CT-1010-02
A3: Steel Structure Works | B3: Area barricading | C3: Material inspection | D3: Trial fit-up | E3: Strucutre Assembly | F3: Formwork installation | G3: Pipe erection | H3: Cable tray installation | I3: Instrument mounting | J3: Surface inspection | K3: Dimensional survey | M3: Yard 3 | N3: CT-1010-20
A4: Grouting Works | B4: Safety signage installation | C4: Material verification with drawings | D4: Temporary bolting | E4: Dismantling | F4: Grout mixing | G4: Fit-up | H4: Cable pulling | I4: Tubing installation | J4: Touch-up painting | K4: Punch list clearance | M4: Laydown | N4: CT-1010-21
A5: Piping Works | B5: Crane mobilization & inspection | C5: Material storage & preservation | D5: Column erection | F5: Grout pouring | G5: Welding | H5: Cable termination | I5: Hook-up works | J5: Final painting | K5: As-built documentation | M5: Parking Area | N5: CT-1010-27
A6: Electrical Works | B6: Manlift mobilization | C6: Material tagging & segregation | D6: Beam erection | F6: Grout curing | G6: NDT inspection | H6: Electrical testing | I6: Loop checking | J6: DFT inspection | K6: Area handover | M6: Long Conveyor | N6: TR-1010-01
A7: Instrumentation Works | B7: Scaffolding mobilization | C7: Equipment Maintenance | D7: Platform installation | G7: Pipe alignment | H7: Dismantling of Electrical Cable | I7: Dismantling of Junction box | M7: Site Office | N7: TR-1010-21
A8: Painting Coating | D8: Ladder & handrail installation | H8: Dismantling of Cable Rack | M8: Main Office | N8: TR-1010-26
A9: Finalization | D9: Alignment (vertical & horizontal) | M9: Reclaimer Substation | N9: TR-1010-20
A10: Idle | D10: Shim installation | M10: Common Area | N10: TR-1010-27
A11: Enco Interenal Transportation | D11: Final bolting | N11: DBD Bld
A12: Alignment of surveyor | D12: Torque tightening | N12: Offloading
A13: Enco Internal Utilities | D13: Bolt marking | N13: Preservation
A14: Equipment Maintenance | D14: Dismantling of Cover | N14: Cable tray supports
A15: Diesel filling | D15: Dismantling of Structure | N15: Loading
D16: Equipment Maintenance | N16: Material Segregation
D17: Diesel filling | N17: Crane Dis/Assembly

Sheet Manpower
F2: =xlookup(Table134526_79101120212223242526[@[Name Surname]],'Manpower'!A1
A3: S/N | B3: ID# | C3: Name | E3: Nationality | F3: Skill | G3: Direct/Indirect | H3: Category
A4: 1 | B4: Encogroup | C4: George Tcheroyan | D4: =_xlfn.XLOOKUP(C4,'April 2026'!A:A,'April 2026'!B:B) -> 121598538 | E4: LEBANESE | F4: Project Manager | G4: Indirect | H4: Manpower
A5: 2 | B5: Encogroup | C5: Vicken Tcheroyan | D5: =_xlfn.XLOOKUP(C5,'April 2026'!A:A,'April 2026'!B:B) -> 121668462 | E5: LEBANESE | F5: Site Manager | G5: Indirect | H5: Manpower
A6: 3 | B6: Encogroup | C6: Mhamed Sheikh | D6: =_xlfn.XLOOKUP(C6,'April 2026'!A:A,'April 2026'!B:B) -> 122370101 | E6: LEBANESE | F6: Quality Manager | G6: Indirect | H6: Manpower
A7: 4 | B7: Encogroup | C7: Rabih Ali El Borji | D7: =_xlfn.XLOOKUP(C7,'April 2026'!A:A,'April 2026'!B:B) -> 123541357 | E7: LEBANESE | F7: Admin Manager | G7: Indirect | H7: Manpower
A8: 5 | B8: Encogroup | C8: Peter Farah | D8: =_xlfn.XLOOKUP(C8,'April 2026'!A:A,'April 2026'!B:B) -> 122045765 | E8: LEBANESE | F8: Lead Mechanical Engineer | G8: Indirect | H8: Manpower
A9: 14 | B9: Encogroup | C9: Abdullah Humaid Al Nofali | D9: =_xlfn.XLOOKUP(C9,'April 2026'!A:A,'April 2026'!B:B) -> 27637114 | E9: OMANI | F9: Driver | G9: Indirect | H9: Manpower
A10: 7 | B10: Encogroup | C10: Maroun Raymond Sarkis | D10: =_xlfn.XLOOKUP(C10,'April 2026'!A:A,'April 2026'!B:B) -> 127387473 | E10: LEBANESE | F10: Mechanical engineer | G10: Indirect | H10: Manpower
A11: 8 | B11: Encogroup | C11: Cherbel Nabih Gebrael | D11: =_xlfn.XLOOKUP(C11,'April 2026'!A:A,'April 2026'!B:B) -> 116894252 | E11: LEBANESE | F11: Purchasing Manager | G11: Indirect | H11: Manpower
A12: 9 | B12: Encogroup | C12: Fenil Paul | D12: =_xlfn.XLOOKUP(C12,'April 2026'!A:A,'April 2026'!B:B) -> 137098196 | E12: Indian | F12: Lifting engineer | G12: Indirect | H12: Manpower
A13: 17 | B13: Encogroup | C13: Abishek Pandey | D13: =_xlfn.XLOOKUP(C13,'April 2026'!A:A,'April 2026'!B:B) -> 123487214 | E13: Indian | F13: Gas Cutter | G13: Direct | H13: Manpower
A14: 239 | B14: BUSHRA | C14: Adil | D14: =_xlfn.XLOOKUP(C14,'April 2026'!A:A,'April 2026'!B:B) -> Not Required | F14: Diesel Re-fueling team | G14: Equipment MP | H14: Manpower
A15: 12 | B15: Encogroup | C15: Gokul Reghu | D15: =_xlfn.XLOOKUP(C15,'April 2026'!A:A,'April 2026'!B:B) -> 123472431 | E15: Indian | F15: Site Coordinator / Timekeeper | G15: Indirect | H15: Manpower
A16: 13 | B16: Encogroup | C16: Fatema Al Abri | D16: =_xlfn.XLOOKUP(C16,'April 2026'!A:A,'April 2026'!B:B) -> 12782421 | E16: OMANI | F16: Admin Assistant | G16: Indirect | H16: Manpower
A17: 219 | B17: Encogroup | C17: Akhilesh Kumar-Welder | D17: =_xlfn.XLOOKUP(C17,'April 2026'!A:A,'April 2026'!B:B) -> U4181508 | F17: Welder | G17: Direct | H17: Manpower
A18: 85 | B18: Encogroup | C18: Ali Riza | D18: =_xlfn.XLOOKUP(C18,'April 2026'!A:A,'April 2026'!B:B) -> 140849254 | E18: TURKIYE | F18: Construction Manager | G18: Indirect | H18: Manpower
A19: 16 | B19: Encogroup | C19: Pappu Kumar Yadaw | D19: =_xlfn.XLOOKUP(C19,'April 2026'!A:A,'April 2026'!B:B) -> 122082769 | E19: Indian | F19: Grinder | G19: Direct | H19: Manpower
A20: 58 | B20: Encogroup | C20: Arun Kumar | D20: =_xlfn.XLOOKUP(C20,'April 2026'!A:A,'April 2026'!B:B) -> 123039392 | E20: Indian | F20: Fitter/Erector | G20: Direct | H20: Manpower
A21: 10 | B21: Encogroup | C21: Arunraj Rajendiren | D21: =_xlfn.XLOOKUP(C21,'April 2026'!A:A,'April 2026'!B:B) -> 118833981 | E21: Indian | F21: Scheduler / Planning Engineer | G21: Indirect | H21: Manpower
A22: 19 | B22: Encogroup | C22: Ameer Ali | D22: =_xlfn.XLOOKUP(C22,'April 2026'!A:A,'April 2026'!B:B) -> 125440631 | E22: PAKISTANI | F22: Rigger | G22: Direct | H22: Manpower
A23: 20 | B23: Encogroup | C23: Wesley Jan Estandarte | D23: =_xlfn.XLOOKUP(C23,'April 2026'!A:A,'April 2026'!B:B) -> 117255966 | E23: Philipino | F23: Mechanical Supervisor | G23: Direct | H23: Manpower
A24: 128 | B24: Encogroup | C24: Ashwini Kumar | D24: =_xlfn.XLOOKUP(C24,'April 2026'!A:A,'April 2026'!B:B) -> 127414586 | E24: Indian | F24: Electrician | G24: Direct | H24: Manpower
A25: 31 | B25: Encogroup | C25: Azzam Ahmed | D25: =_xlfn.XLOOKUP(C25,'April 2026'!A:A,'April 2026'!B:B) -> 124346519 | E25: LEBANESE | F25: Mechanical Foreman | G25: Direct | H25: Manpower
A26: 110 | B26: Encogroup | C26: Bader Al-Buloshi | D26: =_xlfn.XLOOKUP(C26,'April 2026'!A:A,'April 2026'!B:B) -> 15290981 | E26: OMANI | F26: Driver | G26: Indirect | H26: Manpower
A27: 24 | B27: Encogroup | C27: Jaison Marottikkal Lorance | D27: =_xlfn.XLOOKUP(C27,'April 2026'!A:A,'April 2026'!B:B) -> 120892366 | E27: Indian | F27: HSE Officer | G27: Indirect | H27: Manpower
A28: 32 | B28: Encogroup | C28: Bader Nasser Said Masoud Al Nofali | D28: =_xlfn.XLOOKUP(C28,'April 2026'!A:A,'April 2026'!B:B) -> 28065391 | E28: OMANI | F28: Driver | G28: Indirect | H28: Manpower
A29: 26 | B29: Encogroup | C29: Umesh Singh | D29: =_xlfn.XLOOKUP(C29,'April 2026'!A:A,'April 2026'!B:B) -> 137114773 | E29: Indian | F29: Rigger | G29: Direct | H29: Manpower
... A49: 23 | B49: Encogroup | C49: Dhinesh Vaithiyanathan | D49: =_xlfn.XLOOKUP(C49,'April 2026'!A:A,'April 2026'!B:B) -> 140645388 | E49: Indian | F49: Store keeper | G49: Indirect | H49: Manpower
A50: 242 | B50: Al Jaber Heavy Lift | C50: Fawad Ahmed | D50: =_xlfn.XLOOKUP(C50,'April 2026'!A:A,'April 2026'!B:B) -> 102607563 | F50: Technician | G50: Equipment MP | H50: Manpower
A51: 48 | B51: Encogroup | C51: Afaaq Hussain | D51: =_xlfn.XLOOKUP(C51,'April 2026'!A:A,'April 2026'!B:B) -> 126724428 | E51: PAKISTANI | F51: Surveyor | G51: Indirect | H51: Manpower
A52: 49 | B52: Encogroup | C52: Vinod Kumar | D52: =_xlfn.XLOOKUP(C52,'April 2026'!A:A,'April 2026'!B:B) -> 122082863 | E52: Indian | F52: Grinder | G52: Direct | H52: Manpower
A53: 50 | B53: Encogroup | C53: Abhishek Kumar Tiwari | D53: =_xlfn.XLOOKUP(C53,'April 2026'!A:A,'April 2026'!B:B) -> 140742144 | E53: Indian | F53: Assistant/Helper | G53: Direct | H53: Manpower
A54: 51 | B54: Encogroup | C54: Ranaanand Kumar | D54: =_xlfn.XLOOKUP(C54,'April 2026'!A:A,'April 2026'!B:B) -> 140742088 | E54: Indian | F54: Fitter/Erector | G54: Direct | H54: Manpower
A55: 52 | B55: Encogroup | C55: Deepak Kumar | D55: =_xlfn.XLOOKUP(C55,'April 2026'!A:A,'April 2026'!B:B) -> 140742125 | E55: Indian | F55: Assistant/Helper | G55: Direct | H55: Manpower
A56: 6 | B56: Encogroup | C56: George Zouhair Abi Farah | D56: =_xlfn.XLOOKUP(C56,'April 2026'!A:A,'April 2026'!B:B) -> 121820536 | E56: LEBANESE | F56: Facility Management | G56: Indirect | H56: Manpower
A57: 95 | B57: Encogroup | C57: Ghulam Qadir Muhammad Yousaf | D57: =_xlfn.XLOOKUP(C57,'April 2026'!A:A,'April 2026'!B:B) -> 124398279 | E57: PAKISTANI | F57: Permit Receiver | G57: Indirect | H57: Manpower
A58: 55 | B58: Encogroup | C58: Sujeet Kumar | D58: =_xlfn.XLOOKUP(C58,'April 2026'!A:A,'April 2026'!B:B) -> 140742177 | E58: Indian | F58: Grinder | G58: Direct | H58: Manpower
A59: 133 | B59: Encogroup | C59: Gurpreet Sing | D59: =_xlfn.XLOOKUP(C59,'April 2026'!A:A,'April 2026'!B:B) -> 86971535 | E59: Indian | F59: Crane Operator | G59: Equipment MP | H59: Manpower
A60: 70 | B60: Encogroup | C60: Gyenendra Kumar Gupta | D60: =_xlfn.XLOOKUP(C60,'April 2026'!A:A,'April 2026'!B:B) -> 140809004 | E60: Indian | F60: Fitter/Erector | G60: Direct | H60: Manpower
...

Sheet April 2026
A1: Name | B1: ID # | C1: Skill | WZY1: =SUBTOTAL(9,D1:WZX1) -> 0
A2: Aaisha Abdallah Said AL Balushi | B2: 12704175 | C2: Process Engineer
A3: Abdullah Humaid Al Nofali | B3: 27637114 | C3: Junior PRO
A4: Abdullah Khalfan Humaid Al Saidi | B4: 7065269 | C4: Lowbed Trailer Driver
A5: Abhishek Kumar | B5: 140545152 | C5: Painter
A6: Abhishek Kumar Tiwari | B6: 140742144 | C6: Helper
A7: Abid Hussain | B7: 112778626 | C7: Crane Operator -150T
A8: Abishek Pandey | B8: 123487214
A9: Adhikesavan Chandrasekaran | B9: 141793239 | C9: QC Document Controller
A10: Adil | B10: Not Required
A11: Afaaq Hussain | B11: 126724428 | C11: Surveyor
A12: Ahmad Kerbaj | B12: 132915855 | C12: Mechanical Supervisor
A13: AHMED KHADEEM SAID AL TOURASHI | B13: 19753414 | C13: Bus Driver
A14: Aiyaj Najirhussain Patel | B14: AN071596 | C14: Gas Cutter
A15: Ajin Paramesvaran | B15: 141377747 | C15: Painter
A16: Ajithkumar Aravindakshanpillai | B16: 140693697 | C16: HSE Officer
A17: Akhilesh Kumar | B17: 141359235 | C17: Welder
A18: Akhilesh Kumar | B18: 122179745 | C18: Fitter
A19: Akhilesh Kumar-Welder | B19: U4181508
A20: Akram Hossain | B20: 126825676 | C20: Fitter
A21: Akther Sanaulla | B21: 89442153 | C21: Fitter
A22: Alamin Robeul Islam | B22: 98021462 | C22: Mechanical Foreman
A23: Alamin Sheikh | B23: 128486351 | C23: Helper
A24: Ali Haider | B24: 100398391
A25: Ali Riza | B25: 140849254 | C25: Construction Manager
A26: Alla Said Abdallah Al Jabri | B26: 12441043 | C26: IT Engineer
A27: Amal Kannoor Ramachandran | B27: 141322485 | C27: Electrical Engineer
A28: Amdadul Haque | B28: 131662411 | C28: Helper
A29: Ameer Ali | B29: 125440631 | C29: Rigger
A30: Amit Gupta | B30: 140844783 | C30: Painter
A31: Amna Aadil Khalaf Al-Marroushi | B31: 14496555 | C31: Admin Assistant
A32: Amran Hamood Marhoon Al-Hashemi | B32: 10612625 | C32: Junior HSE Officer
A33: Anandbabu subbiah | B33: 81612139 | C33: Mechanic
A34: Aneesh Joseph | B34: 141253376 | C34: Store Keeper
A35: Anil Baitha | B35: AD797743 | C35: Gas Cutter
A36: Aravind Kumar Tiwari | B36: 141818413 | C36: Fitter
A37: Arifur Rahman | B37: 115731078 | C37: Scaffolder
A38: Arun Baby | B38: 128954904 | C38: Nurse
A39: Arun Kumar | B39: 123039392
A40: Arunbhai Balubhai | B40: 140764355 | C40: Fitter/Erector
...
